#VRML_SIM R2019a utf8
WorldInfo {
}
Viewpoint {
  orientation -0.5198655248775099 0.8435065051646046 0.13504299977720358 0.5974847201646637
  position 3.0491416958359188 2.795538388407852 3.722860037221401
}
TexturedBackground {
}
TexturedBackgroundLight {
}
Floor {
}
Solid {
  translation 0 0.025 0
  children [
    DEF GR_1 Group {
      children [
        Shape {
          appearance DEF A_1 PBRAppearance {
            baseColor 0.5411764705882353 0.8862745098039215 0.20392156862745098
          }
          geometry DEF G_1 Box {
            size 1 0.05 1
          }
        }
        Transform {
          translation 0 0.95 0
          rotation 1 0 0 0
          children [
            Shape {
              appearance USE A_1
              geometry USE G_1
            }
          ]
        }
        DEF GR_2 Group {
          children [
            Transform {
              translation 0.495 0.475 0.45
              children [
                Shape {
                  appearance DEF A_2 PBRAppearance {
                    baseColor 0.6784313725490196 0.4980392156862745 0.6588235294117647
                  }
                  geometry DEF G_3Face Box {
                    size 0.01 0.9 0.1
                  }
                }
                Transform {
                  translation 0 0 -0.9
                  children [
                    Shape {
                      appearance USE A_2
                      geometry USE G_3Face
                    }
                  ]
                }
                Transform {
                  translation 0 0.4 -0.45
                  rotation 1 0 0 1.57
                  children [
                    Shape {
                      appearance USE A_2
                      geometry USE G_3Face
                    }
                  ]
                }
                Transform {
                  translation 0 -0.4 -0.45
                  rotation 1 0 0 1.57
                  children [
                    Shape {
                      appearance USE A_2
                      geometry USE G_3Face
                    }
                  ]
                }
                Transform {
                  translation 0 0 -0.45
                  rotation 1 0 0 0.85
                  children [
                    Shape {
                      appearance USE A_2
                      geometry DEF G_3FACE_1 Box {
                        size 0.01 1.0999999999999999 0.07
                      }
                    }
                  ]
                }
                Transform {
                  translation 0 0 -0.45
                  rotation 1 0 0 -0.85
                  children [
                    Shape {
                      appearance USE A_2
                      geometry USE G_3FACE_1
                    }
                  ]
                }
              ]
            }
          ]
        }
        DEF GR_3 Group {
          children [
            Transform {
              translation -0.495 0.475 0.45
              children [
                Shape {
                  appearance USE A_2
                  geometry USE G_3Face
                }
                Transform {
                  translation 0 0 -0.9
                  children [
                    Shape {
                      appearance USE A_2
                      geometry USE G_3Face
                    }
                  ]
                }
                Transform {
                  translation 0 0.4 -0.45
                  rotation 1 0 0 1.57
                  children [
                    Shape {
                      appearance USE A_2
                      geometry USE G_3Face
                    }
                  ]
                }
                Transform {
                  translation 0 -0.4 -0.45
                  rotation 1 0 0 1.57
                  children [
                    Shape {
                      appearance USE A_2
                      geometry USE G_3Face
                    }
                  ]
                }
                Transform {
                  translation 0 0 -0.45
                  rotation 1 0 0 0.85
                  children [
                    Shape {
                      appearance USE A_2
                      geometry USE G_3FACE_1
                    }
                  ]
                }
                Transform {
                  translation 0 0 -0.45
                  rotation 1 0 0 -0.85
                  children [
                    Shape {
                      appearance USE A_2
                      geometry USE G_3FACE_1
                    }
                  ]
                }
              ]
            }
          ]
        }
        DEF GR_4 Group {
          children [
            Transform {
              translation 0.44 0.475 0.495
              children [
                Shape {
                  appearance DEF A_3 PBRAppearance {
                    baseColor 0.9372549019607843 0.1607843137254902 0.1607843137254902
                  }
                  geometry DEF G_FACE4 Box {
                    size 0.1 0.9 0.01
                  }
                }
                Transform {
                  translation -0.88 0 0
                  children [
                    Shape {
                      appearance USE A_3
                      geometry USE G_FACE4
                    }
                  ]
                }
                Transform {
                  translation -0.44 0.4 0
                  rotation 0 0 1 1.57
                  children [
                    Shape {
                      appearance USE A_3
                      geometry USE G_FACE4
                    }
                  ]
                }
                Transform {
                  translation -0.44 -0.4 0
                  rotation 0 0 1 1.57
                  children [
                    Shape {
                      appearance USE A_3
                      geometry USE G_FACE4
                    }
                  ]
                }
                Transform {
                  translation -0.44 0 0
                  rotation 0 0 1 0.85
                  children [
                    Shape {
                      appearance USE A_3
                      geometry DEF G_4FACE_1 Box {
                        size 0.07 1.05 0.01
                      }
                    }
                  ]
                }
                Transform {
                  translation -0.44 0 0
                  rotation 0 0 1 -0.85
                  children [
                    Shape {
                      appearance USE A_3
                      geometry USE G_4FACE_1
                    }
                  ]
                }
              ]
            }
          ]
        }
        DEF GR_5 Group {
          children [
            Transform {
              translation 0.44 0.475 -0.495
              children [
                Shape {
                  appearance USE A_3
                  geometry USE G_FACE4
                }
                Transform {
                  translation -0.88 0 0
                  children [
                    Shape {
                      appearance USE A_3
                      geometry USE G_FACE4
                    }
                  ]
                }
                Transform {
                  translation -0.44 0.4 0
                  rotation 0 0 1 1.57
                  children [
                    Shape {
                      appearance USE A_3
                      geometry USE G_FACE4
                    }
                  ]
                }
                Transform {
                  translation -0.44 -0.4 0
                  rotation 0 0 1 1.57
                  children [
                    Shape {
                      appearance USE A_3
                      geometry USE G_FACE4
                    }
                  ]
                }
                Transform {
                  translation -0.44 0 0
                  rotation 0 0 1 0.85
                  children [
                    Shape {
                      appearance USE A_3
                      geometry USE G_4FACE_1
                    }
                  ]
                }
                Transform {
                  translation -0.44 0 0
                  rotation 0 0 1 0.85
                  children [
                    Shape {
                      appearance USE A_3
                      geometry USE G_4FACE_1
                    }
                  ]
                }
              ]
            }
          ]
        }
        Group {
          children [
            Transform {
              translation 0 1.225 0
              children [
                Shape {
                  appearance PBRAppearance {
                    baseColor 0 0 0
                  }
                  geometry Cylinder {
                    height 0.5
                    radius 0.1
                  }
                }
                HingeJoint {
                  jointParameters HingeJointParameters {
                    axis 0 1 0
                    anchor 0 0.25 0
                    staticFriction 0.02
                  }
                  endPoint Solid {
                    translation 0.35 0.275 0
                    children [
                      Shape {
                        appearance PBRAppearance {
                          baseColor 0.9882352941176471 0.9137254901960784 0.30980392156862746
                        }
                        geometry DEF G_M Box {
                          size 0.7 0.05 0.05
                        }
                      }
                      HingeJoint {
                        jointParameters HingeJointParameters {
                          anchor 0.35 0 0
                          staticFriction 0.01
                        }
                        endPoint Solid {
                          translation 0.355 0 0
                          rotation 1 0 0 0
                          children [
                            DEF GR_E Group {
                              children [
                                Shape {
                                  appearance DEF A_E PBRAppearance {
                                    baseColor 0.7294117647058823 0.7411764705882353 0.7137254901960784
                                  }
                                  geometry DEF G_E Box {
                                    size 0.01 1 0.05
                                  }
                                }
                                Transform {
                                  rotation 1 0 0 1.57
                                  children [
                                    Shape {
                                      appearance USE A_E
                                      geometry USE G_E
                                    }
                                  ]
                                }
                              ]
                            }
                          ]
                          boundingObject USE GR_E
                          physics Physics {
                          }
                        }
                      }
                    ]
                    boundingObject USE G_M
                    physics Physics {
                    }
                  }
                }
              ]
            }
          ]
        }
      ]
    }
  ]
}
